<?xml version="1.0"?>
<robot name="cart_pole">

  <link name="world"/>

  <link name="rail">
    <visual>
      <geometry> <box size="22 0.05 0.05"/> </geometry>
      <material name="grey"> <color rgba="0.5 0.5 0.5 1"/> </material>
    </visual>
    <collision>
      <geometry> <box size="22 0.05 0.05"/> </geometry>
    </collision>
    <inertial>
      <mass value="10.0"/>
      <inertia ixx="0.1" ixy="0" ixz="0" iyy="0.1" iyz="0" izz="0.1"/>
    </inertial>
  </link>

  <joint name="world_to_rail" type="fixed">
    <parent link="world"/>
    <child link="rail"/>
    <origin xyz="0 0 1.0"/>
  </joint>

  <link name="cart">
    <visual>
      <geometry> <box size="0.5 0.2 0.1"/> </geometry>
      <material name="blue"> <color rgba="0 0 0.8 1"/> </material>
    </visual>
    <collision>
      <geometry> <box size="0.5 0.2 0.1"/> </geometry>
    </collision>
    <inertial>
      <mass value="1.0"/>
      <inertia ixx="0.01" ixy="0" ixz="0" iyy="0.01" iyz="0" izz="0.01"/>
    </inertial>
  </link>

  <joint name="cart_joint" type="prismatic">
    <parent link="rail"/>
    <child link="cart"/>
    <axis xyz="1 0 0"/>
    <limit lower="-10" upper="10" effort="10000.0" velocity="100.0"/>
    <dynamics damping="0.1" friction="0.05"/>
  </joint>

  <link name="pole">
    <visual>
      <origin xyz="0 0 0.5" rpy="0 0 0"/>
      <geometry> <cylinder length="1.0" radius="0.02"/> </geometry>
      <material name="red"> <color rgba="0.8 0 0 1"/> </material>
    </visual>
    <collision>
      <origin xyz="0 0 0.5" rpy="0 0 0"/>
      <geometry> <cylinder length="1.0" radius="0.02"/> </geometry>
    </collision>
    <inertial>
      <origin xyz="0 0 0.5" rpy="0 0 0"/>
      <mass value="0.2"/>
      <inertia ixx="0.0001" ixy="0" ixz="0" iyy="0.0001" iyz="0" izz="0.0001"/>
    </inertial>
  </link>

  <joint name="pole_joint" type="revolute">
    <parent link="cart"/>
    <child link="pole"/>
    <origin xyz="0 0 0.05" rpy="0 0 0"/>
    <axis xyz="0 1 0"/>
    <limit lower="-3.0" upper="3.0" effort="1000.0" velocity="100.0"/>
    <dynamics damping="0.1" friction="0.005"/>
  </joint>

  <gazebo>
    <plugin name="gazebo_ros_joint_state_publisher" filename="libgazebo_ros_joint_state_publisher.so">
      <ros>
        
        <remapping>joint_states:=joint_states</remapping>
      </ros>
      <update_rate>100</update_rate>
      <joint_name>cart_joint</joint_name>
      <joint_name>pole_joint</joint_name>
    </plugin>
  </gazebo>

  <gazebo>
    <plugin name="gazebo_ros_force" filename="libgazebo_ros_force.so">
      <ros>
        
        <remapping>gazebo_ros_force:=cart_force</remapping>
      </ros>
      <link_name>cart</link_name>
      <force_frame>link</force_frame>
    </plugin>
  </gazebo>

  <gazebo reference="rail"><material>Gazebo/DarkGrey</material></gazebo>
  <gazebo reference="cart"><material>Gazebo/Blue</material></gazebo>
  <gazebo reference="pole"><material>Gazebo/Red</material></gazebo>

</robot>
